15396874051c
*** Reading local file: /home/project/airflow/logs/dag_id=capstone-dag/run_id=manual__2023-03-22T14:22:39.962841+00:00/task_id=extract_data/attempt=1.log
[2023-03-22 14:22:41,813] {taskinstance.py:1179} INFO - Dependencies all met for <TaskInstance: capstone-dag.extract_data manual__2023-03-22T14:22:39.962841+00:00 [queued]>
[2023-03-22 14:22:41,857] {taskinstance.py:1179} INFO - Dependencies all met for <TaskInstance: capstone-dag.extract_data manual__2023-03-22T14:22:39.962841+00:00 [queued]>
[2023-03-22 14:22:41,858] {taskinstance.py:1376} INFO - 
--------------------------------------------------------------------------------
[2023-03-22 14:22:41,858] {taskinstance.py:1377} INFO - Starting attempt 1 of 2
[2023-03-22 14:22:41,858] {taskinstance.py:1378} INFO - 
--------------------------------------------------------------------------------
[2023-03-22 14:22:41,899] {taskinstance.py:1397} INFO - Executing <Task(BashOperator): extract_data> on 2023-03-22 14:22:39.962841+00:00
[2023-03-22 14:22:41,919] {standard_task_runner.py:52} INFO - Started process 4161 to run task
[2023-03-22 14:22:41,927] {standard_task_runner.py:79} INFO - Running: ['***', 'tasks', 'run', 'capstone-dag', 'extract_data', 'manual__2023-03-22T14:22:39.962841+00:00', '--job-id', '2', '--raw', '--subdir', 'DAGS_FOLDER/process_web_log.py', '--cfg-path', '/tmp/tmplzu54vrc', '--error-file', '/tmp/tmpoo1pigrw']
[2023-03-22 14:22:41,928] {standard_task_runner.py:80} INFO - Job 2: Subtask extract_data
[2023-03-22 14:22:42,087] {task_command.py:371} INFO - Running <TaskInstance: capstone-dag.extract_data manual__2023-03-22T14:22:39.962841+00:00 [running]> on host 15396874051c
[2023-03-22 14:22:42,244] {taskinstance.py:1591} INFO - Exporting the following env vars:
AIRFLOW_CTX_DAG_EMAIL=erwin@somemail.com
AIRFLOW_CTX_DAG_OWNER=Erwin Pasia
AIRFLOW_CTX_DAG_ID=capstone-dag
AIRFLOW_CTX_TASK_ID=extract_data
AIRFLOW_CTX_EXECUTION_DATE=2023-03-22T14:22:39.962841+00:00
AIRFLOW_CTX_TRY_NUMBER=1
AIRFLOW_CTX_DAG_RUN_ID=manual__2023-03-22T14:22:39.962841+00:00
[2023-03-22 14:22:42,246] {subprocess.py:62} INFO - Tmp dir root location: 
 /tmp
[2023-03-22 14:22:42,247] {subprocess.py:74} INFO - Running command: ['bash', '-c', 'cut -d":" -f1 accesslog.txt > extracted-data.txt']
[2023-03-22 14:22:42,271] {subprocess.py:85} INFO - Output:
[2023-03-22 14:22:42,279] {subprocess.py:92} INFO - cut: accesslog.txt: No such file or directory
[2023-03-22 14:22:42,280] {subprocess.py:96} INFO - Command exited with return code 1
[2023-03-22 14:22:42,318] {taskinstance.py:1909} ERROR - Task failed with exception
Traceback (most recent call last):
  File "/home/airflow/.local/lib/python3.7/site-packages/airflow/operators/bash.py", line 195, in execute
    f'Bash command failed. The command returned a non-zero exit code {result.exit_code}.'
airflow.exceptions.AirflowException: Bash command failed. The command returned a non-zero exit code 1.
[2023-03-22 14:22:42,323] {taskinstance.py:1420} INFO - Marking task as UP_FOR_RETRY. dag_id=capstone-dag, task_id=extract_data, execution_date=20230322T142239, start_date=20230322T142241, end_date=20230322T142242
[2023-03-22 14:22:42,349] {warnings.py:110} WARNING - /home/***/.local/lib/python3.7/site-packages/***/utils/email.py:119: PendingDeprecationWarning: Fetching SMTP credentials from configuration variables will be deprecated in a future release. Please set credentials using a connection instead.
  send_mime_email(e_from=mail_from, e_to=recipients, mime_msg=msg, conn_id=conn_id, dryrun=dryrun)

[2023-03-22 14:22:42,349] {configuration.py:552} WARNING - section/key [smtp/smtp_user] not found in config
[2023-03-22 14:22:42,349] {email.py:228} INFO - Email alerting: attempt 1
[2023-03-22 14:22:42,363] {configuration.py:552} WARNING - section/key [smtp/smtp_user] not found in config
[2023-03-22 14:22:42,364] {email.py:228} INFO - Email alerting: attempt 1
[2023-03-22 14:22:42,364] {taskinstance.py:1964} ERROR - Failed to send email to: ['erwin@somemail.com']
Traceback (most recent call last):
  File "/home/airflow/.local/lib/python3.7/site-packages/airflow/models/taskinstance.py", line 1471, in _run_raw_task
    self._execute_task_with_callbacks(context, test_mode)
  File "/home/airflow/.local/lib/python3.7/site-packages/airflow/models/taskinstance.py", line 1618, in _execute_task_with_callbacks
    result = self._execute_task(context, task_orig)
  File "/home/airflow/.local/lib/python3.7/site-packages/airflow/models/taskinstance.py", line 1679, in _execute_task
    result = execute_callable(context=context)
  File "/home/airflow/.local/lib/python3.7/site-packages/airflow/operators/bash.py", line 195, in execute
    f'Bash command failed. The command returned a non-zero exit code {result.exit_code}.'
airflow.exceptions.AirflowException: Bash command failed. The command returned a non-zero exit code 1.

During handling of the above exception, another exception occurred:

Traceback (most recent call last):
  File "/home/airflow/.local/lib/python3.7/site-packages/airflow/models/taskinstance.py", line 2346, in email_alert
    send_email(task.email, subject, html_content)
  File "/home/airflow/.local/lib/python3.7/site-packages/airflow/utils/email.py", line 71, in send_email
    **kwargs,
  File "/home/airflow/.local/lib/python3.7/site-packages/airflow/utils/email.py", line 119, in send_email_smtp
    send_mime_email(e_from=mail_from, e_to=recipients, mime_msg=msg, conn_id=conn_id, dryrun=dryrun)
  File "/home/airflow/.local/lib/python3.7/site-packages/airflow/utils/email.py", line 230, in send_mime_email
    smtp_conn = _get_smtp_connection(smtp_host, smtp_port, smtp_timeout, smtp_ssl)
  File "/home/airflow/.local/lib/python3.7/site-packages/airflow/utils/email.py", line 264, in _get_smtp_connection
    else smtplib.SMTP(host=host, port=port, timeout=timeout)
  File "/usr/local/lib/python3.7/smtplib.py", line 251, in __init__
    (code, msg) = self.connect(host, port)
  File "/usr/local/lib/python3.7/smtplib.py", line 336, in connect
    self.sock = self._get_socket(host, port, self.timeout)
  File "/usr/local/lib/python3.7/smtplib.py", line 307, in _get_socket
    self.source_address)
  File "/usr/local/lib/python3.7/socket.py", line 728, in create_connection
    raise err
  File "/usr/local/lib/python3.7/socket.py", line 716, in create_connection
    sock.connect(sa)
OSError: [Errno 99] Cannot assign requested address

During handling of the above exception, another exception occurred:

Traceback (most recent call last):
  File "/home/airflow/.local/lib/python3.7/site-packages/airflow/models/taskinstance.py", line 1962, in handle_failure
    self.email_alert(error, task)
  File "/home/airflow/.local/lib/python3.7/site-packages/airflow/models/taskinstance.py", line 2348, in email_alert
    send_email(task.email, subject, html_content_err)
  File "/home/airflow/.local/lib/python3.7/site-packages/airflow/utils/email.py", line 71, in send_email
    **kwargs,
  File "/home/airflow/.local/lib/python3.7/site-packages/airflow/utils/email.py", line 119, in send_email_smtp
    send_mime_email(e_from=mail_from, e_to=recipients, mime_msg=msg, conn_id=conn_id, dryrun=dryrun)
  File "/home/airflow/.local/lib/python3.7/site-packages/airflow/utils/email.py", line 230, in send_mime_email
    smtp_conn = _get_smtp_connection(smtp_host, smtp_port, smtp_timeout, smtp_ssl)
  File "/home/airflow/.local/lib/python3.7/site-packages/airflow/utils/email.py", line 264, in _get_smtp_connection
    else smtplib.SMTP(host=host, port=port, timeout=timeout)
  File "/usr/local/lib/python3.7/smtplib.py", line 251, in __init__
    (code, msg) = self.connect(host, port)
  File "/usr/local/lib/python3.7/smtplib.py", line 336, in connect
    self.sock = self._get_socket(host, port, self.timeout)
  File "/usr/local/lib/python3.7/smtplib.py", line 307, in _get_socket
    self.source_address)
  File "/usr/local/lib/python3.7/socket.py", line 728, in create_connection
    raise err
  File "/usr/local/lib/python3.7/socket.py", line 716, in create_connection
    sock.connect(sa)
OSError: [Errno 99] Cannot assign requested address
[2023-03-22 14:22:42,390] {standard_task_runner.py:97} ERROR - Failed to execute job 2 for task extract_data (Bash command failed. The command returned a non-zero exit code 1.; 4161)
[2023-03-22 14:22:42,418] {local_task_job.py:156} INFO - Task exited with return code 1
[2023-03-22 14:22:42,490] {local_task_job.py:273} INFO - 0 downstream tasks scheduled from follow-on schedule check

15396874051c
*** Reading local file: /home/project/airflow/logs/dag_id=capstone-dag/run_id=manual__2023-03-22T14:22:39.962841+00:00/task_id=extract_data/attempt=2.log
[2023-03-22 14:27:44,458] {taskinstance.py:1179} INFO - Dependencies all met for <TaskInstance: capstone-dag.extract_data manual__2023-03-22T14:22:39.962841+00:00 [queued]>
[2023-03-22 14:27:44,478] {taskinstance.py:1179} INFO - Dependencies all met for <TaskInstance: capstone-dag.extract_data manual__2023-03-22T14:22:39.962841+00:00 [queued]>
[2023-03-22 14:27:44,479] {taskinstance.py:1376} INFO - 
--------------------------------------------------------------------------------
[2023-03-22 14:27:44,479] {taskinstance.py:1377} INFO - Starting attempt 2 of 2
[2023-03-22 14:27:44,479] {taskinstance.py:1378} INFO - 
--------------------------------------------------------------------------------
[2023-03-22 14:27:44,517] {taskinstance.py:1397} INFO - Executing <Task(BashOperator): extract_data> on 2023-03-22 14:22:39.962841+00:00
[2023-03-22 14:27:44,537] {standard_task_runner.py:52} INFO - Started process 4390 to run task
[2023-03-22 14:27:44,553] {standard_task_runner.py:79} INFO - Running: ['***', 'tasks', 'run', 'capstone-dag', 'extract_data', 'manual__2023-03-22T14:22:39.962841+00:00', '--job-id', '3', '--raw', '--subdir', 'DAGS_FOLDER/process_web_log.py', '--cfg-path', '/tmp/tmpt80ietk6', '--error-file', '/tmp/tmpk9e1iw0c']
[2023-03-22 14:27:44,553] {standard_task_runner.py:80} INFO - Job 3: Subtask extract_data
[2023-03-22 14:27:44,799] {task_command.py:371} INFO - Running <TaskInstance: capstone-dag.extract_data manual__2023-03-22T14:22:39.962841+00:00 [running]> on host 15396874051c
[2023-03-22 14:27:45,212] {taskinstance.py:1591} INFO - Exporting the following env vars:
AIRFLOW_CTX_DAG_EMAIL=erwin@somemail.com
AIRFLOW_CTX_DAG_OWNER=Erwin Pasia
AIRFLOW_CTX_DAG_ID=capstone-dag
AIRFLOW_CTX_TASK_ID=extract_data
AIRFLOW_CTX_EXECUTION_DATE=2023-03-22T14:22:39.962841+00:00
AIRFLOW_CTX_TRY_NUMBER=2
AIRFLOW_CTX_DAG_RUN_ID=manual__2023-03-22T14:22:39.962841+00:00
[2023-03-22 14:27:45,219] {subprocess.py:62} INFO - Tmp dir root location: 
 /tmp
[2023-03-22 14:27:45,220] {subprocess.py:74} INFO - Running command: ['bash', '-c', 'cut -d":" -f1 accesslog.txt > extracted-data.txt']
[2023-03-22 14:27:45,314] {subprocess.py:85} INFO - Output:
[2023-03-22 14:27:45,330] {subprocess.py:92} INFO - cut: accesslog.txt: No such file or directory
[2023-03-22 14:27:45,331] {subprocess.py:96} INFO - Command exited with return code 1
[2023-03-22 14:27:45,397] {taskinstance.py:1909} ERROR - Task failed with exception
Traceback (most recent call last):
  File "/home/airflow/.local/lib/python3.7/site-packages/airflow/operators/bash.py", line 195, in execute
    f'Bash command failed. The command returned a non-zero exit code {result.exit_code}.'
airflow.exceptions.AirflowException: Bash command failed. The command returned a non-zero exit code 1.
[2023-03-22 14:27:45,403] {taskinstance.py:1420} INFO - Marking task as FAILED. dag_id=capstone-dag, task_id=extract_data, execution_date=20230322T142239, start_date=20230322T142744, end_date=20230322T142745
[2023-03-22 14:27:45,462] {warnings.py:110} WARNING - /home/***/.local/lib/python3.7/site-packages/***/utils/email.py:119: PendingDeprecationWarning: Fetching SMTP credentials from configuration variables will be deprecated in a future release. Please set credentials using a connection instead.
  send_mime_email(e_from=mail_from, e_to=recipients, mime_msg=msg, conn_id=conn_id, dryrun=dryrun)

[2023-03-22 14:27:45,462] {configuration.py:552} WARNING - section/key [smtp/smtp_user] not found in config
[2023-03-22 14:27:45,462] {email.py:228} INFO - Email alerting: attempt 1
[2023-03-22 14:27:45,495] {configuration.py:552} WARNING - section/key [smtp/smtp_user] not found in config
[2023-03-22 14:27:45,496] {email.py:228} INFO - Email alerting: attempt 1
[2023-03-22 14:27:45,497] {taskinstance.py:1964} ERROR - Failed to send email to: ['erwin@somemail.com']
Traceback (most recent call last):
  File "/home/airflow/.local/lib/python3.7/site-packages/airflow/models/taskinstance.py", line 1471, in _run_raw_task
    self._execute_task_with_callbacks(context, test_mode)
  File "/home/airflow/.local/lib/python3.7/site-packages/airflow/models/taskinstance.py", line 1618, in _execute_task_with_callbacks
    result = self._execute_task(context, task_orig)
  File "/home/airflow/.local/lib/python3.7/site-packages/airflow/models/taskinstance.py", line 1679, in _execute_task
    result = execute_callable(context=context)
  File "/home/airflow/.local/lib/python3.7/site-packages/airflow/operators/bash.py", line 195, in execute
    f'Bash command failed. The command returned a non-zero exit code {result.exit_code}.'
airflow.exceptions.AirflowException: Bash command failed. The command returned a non-zero exit code 1.

During handling of the above exception, another exception occurred:

Traceback (most recent call last):
  File "/home/airflow/.local/lib/python3.7/site-packages/airflow/models/taskinstance.py", line 2346, in email_alert
    send_email(task.email, subject, html_content)
  File "/home/airflow/.local/lib/python3.7/site-packages/airflow/utils/email.py", line 71, in send_email
    **kwargs,
  File "/home/airflow/.local/lib/python3.7/site-packages/airflow/utils/email.py", line 119, in send_email_smtp
    send_mime_email(e_from=mail_from, e_to=recipients, mime_msg=msg, conn_id=conn_id, dryrun=dryrun)
  File "/home/airflow/.local/lib/python3.7/site-packages/airflow/utils/email.py", line 230, in send_mime_email
    smtp_conn = _get_smtp_connection(smtp_host, smtp_port, smtp_timeout, smtp_ssl)
  File "/home/airflow/.local/lib/python3.7/site-packages/airflow/utils/email.py", line 264, in _get_smtp_connection
    else smtplib.SMTP(host=host, port=port, timeout=timeout)
  File "/usr/local/lib/python3.7/smtplib.py", line 251, in __init__
    (code, msg) = self.connect(host, port)
  File "/usr/local/lib/python3.7/smtplib.py", line 336, in connect
    self.sock = self._get_socket(host, port, self.timeout)
  File "/usr/local/lib/python3.7/smtplib.py", line 307, in _get_socket
    self.source_address)
  File "/usr/local/lib/python3.7/socket.py", line 728, in create_connection
    raise err
  File "/usr/local/lib/python3.7/socket.py", line 716, in create_connection
    sock.connect(sa)
OSError: [Errno 99] Cannot assign requested address

During handling of the above exception, another exception occurred:

Traceback (most recent call last):
  File "/home/airflow/.local/lib/python3.7/site-packages/airflow/models/taskinstance.py", line 1962, in handle_failure
    self.email_alert(error, task)
  File "/home/airflow/.local/lib/python3.7/site-packages/airflow/models/taskinstance.py", line 2348, in email_alert
    send_email(task.email, subject, html_content_err)
  File "/home/airflow/.local/lib/python3.7/site-packages/airflow/utils/email.py", line 71, in send_email
    **kwargs,
  File "/home/airflow/.local/lib/python3.7/site-packages/airflow/utils/email.py", line 119, in send_email_smtp
    send_mime_email(e_from=mail_from, e_to=recipients, mime_msg=msg, conn_id=conn_id, dryrun=dryrun)
  File "/home/airflow/.local/lib/python3.7/site-packages/airflow/utils/email.py", line 230, in send_mime_email
    smtp_conn = _get_smtp_connection(smtp_host, smtp_port, smtp_timeout, smtp_ssl)
  File "/home/airflow/.local/lib/python3.7/site-packages/airflow/utils/email.py", line 264, in _get_smtp_connection
    else smtplib.SMTP(host=host, port=port, timeout=timeout)
  File "/usr/local/lib/python3.7/smtplib.py", line 251, in __init__
    (code, msg) = self.connect(host, port)
  File "/usr/local/lib/python3.7/smtplib.py", line 336, in connect
    self.sock = self._get_socket(host, port, self.timeout)
  File "/usr/local/lib/python3.7/smtplib.py", line 307, in _get_socket
    self.source_address)
  File "/usr/local/lib/python3.7/socket.py", line 728, in create_connection
    raise err
  File "/usr/local/lib/python3.7/socket.py", line 716, in create_connection
    sock.connect(sa)
OSError: [Errno 99] Cannot assign requested address
[2023-03-22 14:27:45,554] {standard_task_runner.py:97} ERROR - Failed to execute job 3 for task extract_data (Bash command failed. The command returned a non-zero exit code 1.; 4390)
[2023-03-22 14:27:45,592] {local_task_job.py:156} INFO - Task exited with return code 1
[2023-03-22 14:27:45,714] {local_task_job.py:273} INFO - 0 downstream tasks scheduled from follow-on schedule check

